<?xml version="1.0"?>
<robot xmlns:xacro="http://www.ros.org/wiki/xacro">

  <!-- Wheel constants -->
  <xacro:property name="shaft_len" value="0.015" />
  <xacro:property name="shaft_r" value="0.005" />
  <xacro:property name="shaft_xoffset" value="0.023" />
  <xacro:property name="shaft_yoffset" value="0.048" />  
  <xacro:property name="wheelc_len" value="0.015" />
  <xacro:property name="wheelc_r" value = "0.026" />
  <!-- Wheel constants -->

  <!-- Inertia Macro -->
  <xacro:include filename="$(find jetbot_diff_drive)/urdf/includes/gazebo/inertias.xacro" />  
  <!-- Inertia Macro -->

  <!-- Wheel Macro-->
  <xacro:macro name="wheel_parts" params="prefix reflect">
  <link name="${prefix}_wheel_shaft">
    <visual>
      <origin xyz="0 0 0" rpy="${pi/2} 0 0"/>
      <geometry>
        <cylinder radius="${shaft_r}" length="${shaft_len}" />
      </geometry>
      <material name="white"/>
    </visual>
    <collision>
      <origin xyz="0 0 0" rpy="${pi/2} 0 0"/>
      <geometry>
        <cylinder radius="${shaft_r}" length="${shaft_len}" />
      </geometry>
    </collision> 
    <xacro:inertia mass="0.6" />
  </link>
  <joint name="base_${prefix}_wheel_shaft_joint" type="fixed">
    <axis rpy="0 0 0" xyz="0 0 0" />
    <parent link="base_link"/>
    <child link="${prefix}_wheel_shaft"/>
    <origin rpy="0 0 0" xyz="${shaft_xoffset} ${shaft_yoffset*reflect} 0.013" />
  </joint>

  <link name="${prefix}_wheelc">
    <visual>
      <origin rpy="${pi/2} 0 0"/>
      <geometry>
        <cylinder length="${wheelc_len}" radius="${wheelc_r}"/>
      </geometry>
      <material name="white"/>
    </visual>
    <collision>
      <origin rpy="${pi/2} 0 0"/>
      <geometry>
        <cylinder length="${wheelc_len}" radius="${wheelc_r}"/>
      </geometry>
    </collision> 
    <xacro:inertia mass="0.6" />     
  </link>
  <joint name="${prefix}_shaft_wheelc_joint" type="fixed">
    <origin xyz="0 ${reflect*(wheelc_r-0.002)/2} 0"/>    
    <parent link="${prefix}_wheel_shaft"/>
    <child link="${prefix}_wheelc"/>
  </joint>
  
  <link name="${prefix}_wheel">
    <visual>
    <origin rpy="${pi/2} 0 0" xyz="0 0 0" />    
      <geometry>
        <cylinder length="${wheelc_len}" radius="${wheelc_r + 0.0065}"/>
      </geometry>
      <material name="black"/>
    </visual>
    <collision>
    <origin rpy="${pi/2} 0 0" xyz="0 0 0" />    
      <geometry>
        <cylinder length="${wheelc_len}" radius="${wheelc_r + 0.0065}"/>
      </geometry>
    </collision>
    <xacro:inertia mass="0.6"/>    
  </link>
  <joint name="${prefix}_wheel_joint" type="continuous">
    <axis xyz="0 1 0"/>
    <parent link="${prefix}_wheelc"/>
    <child link="${prefix}_wheel"/>
    <origin xyz ="0 ${-0.0001*reflect} 0"/>  
  </joint>
  <xacro:tx prefix="${prefix}" suffix="wheel" />  
  </xacro:macro>
  <!-- Wheel Macro-->

</robot>